# 210129 - JavaScript Day 26

## Chapter 47. 에러 처리 
### 에러 처리의 필요성
- **에러 처리는 상당히 중요!** 실무에서 꼼꼼히 처리해줘야 한다 
- 에러를 최대한 빨리 인식해서 바로 잡는게 핵심

- 다른 언어에서는 기본적으로 `try`, `catch`로 에러 처리 &#8594; c++에서 시작

- 콜백 방식의 비동기 처리에서는 try, catch로도 에러를 잡지 못하는 경우가 있어서 많이 활용되지 않았다 but, es6에서부터 사용가능 범용적으로 

- 에러와 예외는 다르다 (에러와 오류는 비슷해)
- 에러 발생하면 그 곳에서 애플리케이션이 stop됨 그 이후 코드 실행 안됨
  ```jsx
  console.log('[Start]');
  bar(); // 참조 에러 발생, 어플리케이션 종료됨
  console.log('[End]'); // 실행되지 않음
  ```

- try문 뒤에서 에러가 발생할 가능성이 있는 코드를 작성
- try문에서 에러가 발생하면 catch문으로 감
  - `catch (error) {}` : error는 try문에서 발생한 에러 객체를 받음
- 에러는 객체 형식으로 발생
- `null`이 반환되는 건 에러로 보지 않고 예외로 처리

- `try`...`catch`...`finally`
  - try, catch 는 필수
  - finally 는 옵션 : 에러가 발생하든 안하든 상관없이 반드시 한 번 실행
- try, catch로 에러 처리를 해주면 에러가 발생하더라도 후속 처리를 해주고 어플리케이션이 종료되지 않음 

```jsx
try {
  throw new Error('something wrong!'); // 던져줘야 받음
} catch (error) {
  console.log(error);
}
```

### **에러의 전파**

- 에러 객채도 전파가 된다 &#8594; 호출자(caller) 방향으로 전파!
  - 함수객체에 있는 프로퍼티 caller

- 비동기 함수는 에러가 전파되지 않는다 (호출자가 없으니까)
  - 그러므로 try catch를 사용하지 못함 &#8594; 콜백 함수에서 에러 처리를 해줘야했었음
- 프로미스가 등장한 후로 콜백 함수에서 에러 처리하는 건 안티 패턴이 되어버림... 

---

## Chapther 45. 프로미스

- Promise 생성자 함수 존재 ⇒ `promise 객체` 생성 : 인수 하나 전달해야함! 이때 인수는 **콜백 함수**여야한다 
  - 콜백함수에 인수 2개를 전달하게됨 ⇒ `resolve`, `reject`
  - resolve 또는 reject 둘 중 하나만 호출됨
  - promise status : `pending` &#8594; `fulfilled`(resolve) or `rejected`(reject)

```jsx
// 패턴을 외워버려라

const get = url => {
  return new Promise((resolve, reject) => {
    const xhr = new XMLHttpRequest();

    xhr.open('GET', url);
    xhr.send();

    xhr.onload = () => {
      if (xhr.status === 200 || xhr.status === 201) {
        // Success
        resolve(JSON.parse(xhr.response));
      } else {
        // Failur
        reject(xhr.status);
      }
    };
  });
};

get('https://jsonplaceholder.typicode.com/todos/1')
  .then(console.log)
  .catch(console.error);
```

- `same origin` (동일 출처 정책) 
  - 보안 방식의 하나로 A에서 가져온 문서 또는 스크립트가 B에서 가져온 리소스와 상호 작용하는 것을 제한 
  - 동일 출처란? 프로토콜, 포트, 호스트가 모두 같은 경우
  [참고: MDN문서](https://developer.mozilla.org/ko/docs/Web/Security/Same-origin_policy)


```jsx
get('https://jsonplaceholder.typicode.com/todos/1')
  .then( todo => { // 인수에는 resolve(JSON.parse(xhr.response)) resolve의 값이 고대로 넘어옴
    console.log(todo);
  }) // 이건 결국 .then(console.log)와 동일
  .catch(console.error);
  // then은 promise 리턴 
  // then, catch는 결국 후속처리 
```

- .then .catch 전부 promise 객체를 반환!

```jsx
const ajax = (() => {
  const req = (method, url, payload) => {
    return new Promise((resolve, reject) => {
      const xhr = new XMLHttpRequest();
  
      xhr.open(method, url);
      xhr.setRequestHeader('content-type', 'application/json');
      xhr.send(JSON.stringify(payload));
  
      xhr.onload = () => {
        if (xhr.status === 200 || xhr.status === 201) {
          resolve(JSON.parse(xhr.response));
        } else {
          reject(new Error(xhr.status));
        }
      }
    })
  };

  // req함수가 promise객체를 반환함

  return {
    get(url) { // get도 프로미스 객체로 프로미스를 반환해줘야하므로 return 명시
      return req('GET', url);
    },
    post(url, payload) {
      return req('POST', url, payload);
    },
    patch(url, payload) {
      return req('PATCH', url, payload);
    },
    delete(url) {
      return req('DELETE', url);
    }
  };
})();
```

